Workbook

Sheet Summary
A1: Review Dashboard
A3: Total reviews | B3: =COUNTA(Data!$B:$B)-1 -> 2377
A5: Language counts | D5: Aspect counts
A6: Language | B6: Count | D6: Aspect | E6: Mentioned | F6: Positive | G6: Neutral | H6: Negative | I6: Not mentioned
A7: ru | B7: =COUNTIF(Data!$B:$B,A7) -> 1061 | D7: FQ | E7: =COUNTIF(Data!$E:$E,1) -> 1129 | F7: =COUNTIFS(Data!$E:$E,1,Data!$F:$F,"positive") -> 662 | G7: =COUNTIFS(Data!$E:$E,1,Data!$F:$F,"neutral") -> 146 | H7: =COUNTIFS(Data!$E:$E,1,Data!$F:$F,"negative") -> 321 | I7: =COUNTIF(Data!$E:$E,0) -> 1247
A8: kz | B8: =COUNTIF(Data!$B:$B,A8) -> 1003 | D8: SS | E8: =COUNTIF(Data!$G:$G,1) -> 1096 | F8: =COUNTIFS(Data!$G:$G,1,Data!$H:$H,"positive") -> 625 | G8: =COUNTIFS(Data!$G:$G,1,Data!$H:$H,"neutral") -> 70 | H8: =COUNTIFS(Data!$G:$G,1,Data!$H:$H,"negative") -> 401 | I8: =COUNTIF(Data!$G:$G,0) -> 1280
A9: mixed | B9: =COUNTIF(Data!$B:$B,A9) -> 313 | D9: OA | E9: =COUNTIF(Data!$I:$I,1) -> 354 | F9: =COUNTIFS(Data!$I:$I,1,Data!$J:$J,"positive") -> 40 | G9: =COUNTIFS(Data!$I:$I,1,Data!$J:$J,"neutral") -> 77 | H9: =COUNTIFS(Data!$I:$I,1,Data!$J:$J,"negative") -> 237 | I9: =COUNTIF(Data!$I:$I,0) -> 2022
A10: Total | B10: =SUM(B7:B9) -> 2377 | D10: CL | E10: =COUNTIF(Data!$K:$K,1) -> 398 | F10: =COUNTIFS(Data!$K:$K,1,Data!$L:$L,"positive") -> 104 | G10: =COUNTIFS(Data!$K:$K,1,Data!$L:$L,"neutral") -> 91 | H10: =COUNTIFS(Data!$K:$K,1,Data!$L:$L,"negative") -> 203 | I10: =COUNTIF(Data!$K:$K,0) -> 1978
D11: PV | E11: =COUNTIF(Data!$M:$M,1) -> 299 | F11: =COUNTIFS(Data!$M:$M,1,Data!$N:$N,"positive") -> 67 | G11: =COUNTIFS(Data!$M:$M,1,Data!$N:$N,"neutral") -> 54 | H11: =COUNTIFS(Data!$M:$M,1,Data!$N:$N,"negative") -> 178 | I11: =COUNTIF(Data!$M:$M,0) -> 2076
A12: Как читать: | D12: WS | E12: =COUNTIF(Data!$O:$O,1) -> 357 | F12: =COUNTIFS(Data!$O:$O,1,Data!$P:$P,"positive") -> 115 | G12: =COUNTIFS(Data!$O:$O,1,Data!$P:$P,"neutral") -> 27 | H12: =COUNTIFS(Data!$O:$O,1,Data!$P:$P,"negative") -> 215 | I12: =COUNTIF(Data!$O:$O,0) -> 2018
A13: Mentioned = сколько отзывов вообще затрагивают аспект | D13: AM | E13: =COUNTIF(Data!$Q:$Q,1) -> 582 | F13: =COUNTIFS(Data!$Q:$Q,1,Data!$R:$R,"positive") -> 401 | G13: =COUNTIFS(Data!$Q:$Q,1,Data!$R:$R,"neutral") -> 54 | H13: =COUNTIFS(Data!$Q:$Q,1,Data!$R:$R,"negative") -> 127 | I13: =COUNTIF(Data!$Q:$Q,0) -> 1793
A14: Positive / Neutral / Negative = тональность внутри этого аспекта | D14: LO | E14: =COUNTIF(Data!$S:$S,1) -> 274 | F14: =COUNTIFS(Data!$S:$S,1,Data!$T:$T,"positive") -> 103 | G14: =COUNTIFS(Data!$S:$S,1,Data!$T:$T,"neutral") -> 74 | H14: =COUNTIFS(Data!$S:$S,1,Data!$T:$T,"negative") -> 97 | I14: =COUNTIF(Data!$S:$S,0) -> 2100
A15: Примечание:
A16: В части строк review_id пустой, поэтому общий счетчик лучше считать по language или text.
A18: Дополнительно: см. лист "Aspect by Language" для разбивки аспектов по ru / kz / mixed.

Sheet Data
A1: review_id | B1: language | C1: star_rating | D1: text | E1: FQ | F1: FQ_sent | G1: SS | H1: SS_sent | I1: OA | J1: OA_sent | K1: CL | L1: CL_sent | M1: PV | N1: PV_sent | O1: WS | P1: WS_sent | Q1: AM | R1: AM_sent | S1: LO | T1: LO_sent
A2: 1 | B2: ru | C2: 4 | D2: Еда вкусная, персонал вежливый, но заказ ждали слишком долго. | E2: 1 | F2: positive | G2: 1 | H2: positive | I2: 0 | J2: NA | K2: 0 | L2: NA | M2: 0 | N2: NA | O2: 1 | P2: negative | Q2: 0 | R2: NA | S2: 0 | T2: NA
A3: 2 | B3: ru | C3: 2 | D3: В помещении грязно, заказ перепутали, а цена для такого качества завышена. | E3: 0 | F3: NA | G3: 0 | H3: NA | I3: 1 | J3: negative | K3: 1 | L3: negative | M3: 1 | N3: negative | O3: 0 | P3: NA | Q3: 0 | R3: NA | S3: 0 | T3: NA
A4: 3 | B4: ru | C4: 5 | D4: Очень уютное место, удобная локация, кофе свежий и вкусный. | E4: 1 | F4: positive | G4: 0 | H4: NA | I4: 0 | J4: NA | K4: 0 | L4: NA | M4: 0 | N4: NA | O4: 0 | P4: NA | Q4: 1 | R4: positive | S4: 1 | T4: positive
A5: 4 | B5: kz | C5: 3 | D5: Тағам жаман емес, бірақ қызмет баяу және офицанттар көңіл бөлмеді. | E5: 1 | F5: neutral | G5: 1 | H5: negative | I5: 0 | J5: NA | K5: 0 | L5: NA | M5: 0 | N5: NA | O5: 1 | P5: negative | Q5: 0 | R5: NA | S5: 0 | T5: NA
A6: 5 | B6: ru | C6: 5 | D6: очень вкусные бургеры,всем советуюю | E6: 1 | F6: positive | G6: 0 | H6: NA | I6: 0 | J6: NA | K6: 0 | L6: NA | M6: 0 | N6: NA | O6: 0 | P6: NA | Q6: 0 | R6: NA | S6: 0 | T6: NA
A7: 6 | B7: kz | C7: 5 | D7: Тамаша орын! | E7: 0 | F7: NA | G7: 0 | H7: NA | I7: 0 | J7: NA | K7: 0 | L7: NA | M7: 0 | N7: NA | O7: 0 | P7: NA | Q7: 1 | R7: positive | S7: 0 | T7: NA
A8: 7 | B8: kz | C8: 5 | D8: Бүгін түскі асқа Фритос комбо алдым. Тез дайындады. Рахмет | E8: 0 | F8: NA | G8: 0 | H8: NA | I8: 0 | J8: NA | K8: 0 | L8: NA | M8: 0 | N8: NA | O8: 1 | P8: positive | Q8: 0 | R8: NA | S8: 0 | T8: NA
A9: 8 | B9: mixed | C9: 5 | D9: Классический чикен бургер алдым. Тауық еті шырынды, огурчики тұздығы дәмді. Булка жұмсақ. Жалпы ұнады, тағы келемін | E9: 1 | F9: positive | G9: 0 | H9: NA | I9: 0 | J9: NA | K9: 0 | L9: NA | M9: 0 | N9: NA | O9: 0 | P9: NA | Q9: 0 | R9: NA | S9: 0 | T9: NA
A10: 9 | B10: ru | C10: 1 | D10: бургер принесли холодным,хотя ждали почти час,сыр был сырой,худший филиал | E10: 1 | F10: negative | G10: 0 | H10: NA | I10: 0 | J10: NA | K10: 0 | L10: NA | M10: 0 | N10: NA | O10: 1 | P10: negative | Q10: 0 | R10: NA | S10: 0 | T10: NA
A11: 10 | B11: ru | C11: 4 | D11: Самые-самые лучшие пирожки, как дома, всё свежее всегда. | E11: 1 | F11: positive | G11: 0 | H11: NA | I11: 0 | J11: NA | K11: 0 | L11: NA | M11: 0 | N11: NA | O11: 0 | P11: NA | Q11: 0 | R11: NA | S11: 0 | T11: NA
A12: 11 | B12: ru | C12: 5 | D12: Пил кофе и в Риме, и в Париже, но вкуснее, чем капуч на фундучном молоке с фирменными сливками Джинжу, не пробовал ничего! Десерты тоже очень необычные. Ребята-бариста большие молодцы! Что можно улучшить? Маловато места, с посадкой можно что-то придумать? | E12: 1 | F12: positive | G12: 1 | H12: positive | I12: 0 | J12: NA | K12: 0 | L12: NA | M12: 0 | N12: NA | O12: 0 | P12: NA | Q12: 1 | R12: negative | S12: 0 | T12: NA
A13: 12 | B13: ru | C13: 4 | D13: Не очень удобное расположение, от метро идти мин 20 быстрым шагом через промзону. В самом кофе мест очень мало, а желающих очень много(( пирожные очень вкусные, кофе бывает вкуснее. Второй раз именно туда не пойду. | E13: 1 | F13: neutral | G13: 0 | H13: NA | I13: 0 | J13: NA | K13: 0 | L13: NA | M13: 0 | N13: NA | O13: 0 | P13: NA | Q13: 1 | R13: negative | S13: 1 | T13: negative
A14: 13 | B14: ru | C14: 4 | D14: Положительное место с хорошими блюдами, только персонал отличился высокомерием и надменностью, не рекомендую к посещению, останется неприятный осадок. | E14: 1 | F14: positive | G14: 1 | H14: negative | I14: 0 | J14: NA | K14: 0 | L14: NA | M14: 0 | N14: NA | O14: 0 | P14: NA | Q14: 0 | R14: NA | S14: 0 | T14: NA
A15: 14 | B15: ru | C15: 1 | D15: Доставка очень долгая, на рекламной брошюре написано от 500 р доставка бесплатно, а по факту заплатили 100 р за доставку. Чек был на 577 р. Долго плевались от нагара, который был на сковородке с мясом, хруст на зубах неприятен. Испорченное мнение от вашего заведения. | E15: 1 | F15: negative | G15: 0 | H15: NA | I15: 0 | J15: NA | K15: 1 | L15: negative | M15: 1 | N15: negative | O15: 1 | P15: negative | Q15: 0 | R15: NA | S15: 0 | T15: NA
A16: 15 | B16: ru | C16: 5 | D16: Отличная кухня, прекрасный сервис, внимательный персонал. Кафе рекомендую. | E16: 1 | F16: positive | G16: 1 | H16: positive | I16: 0 | J16: NA | K16: 0 | L16: NA | M16: 0 | N16: NA | O16: 0 | P16: NA | Q16: 0 | R16: NA | S16: 0 | T16: NA
A17: 16 | B17: ru | C17: 5 | D17: Очень вкусно! И по-домашнему! Замечательный комплексный обед! Недорого, порции хорошие! | E17: 1 | F17: positive | G17: 0 | H17: NA | I17: 0 | J17: NA | K17: 0 | L17: NA | M17: 1 | N17: positive | O17: 0 | P17: NA | Q17: 0 | R17: NA | S17: 0 | T17: NA
... A153: 152 | B153: kz | C153: 5 | D153: Донері өте дәмді, лавашы жұмсақ, іші құрғақ емес. Қызметкерлер де сыпайы сөйлеп, жақсы әсер қалдырды. | E153: 1 | F153: positive | G153: 1 | H153: positive | I153: 0 | J153: NA | K153: 0 | L153: NA | M153: 0 | N153: NA | O153: 0 | P153: NA | Q153: 0 | R153: NA | S153: 0 | T153: NA
A154: 153 | B154: kz | C154: NA | D154: Тағамдары жаман емес, бірақ ерекше есте қалатындай дәм байқамадым. Бағасы сәл қымбаттау көрінді. | E154: 1 | F154: neutral | G154: 0 | H154: NA | I154: 0 | J154: NA | K154: 0 | L154: NA | M154: 1 | N154: negative | O154: 0 | P154: NA | Q154: 0 | R154: NA | S154: 0 | T154: NA
A155: 154 | B155: kz | C155: NA | D155: Кофесі де, десерті де өте дәмді болды, бәрі жаңа дайындалғаны білініп тұр. Ішіндегі атмосферасы да жайлы екен. | E155: 1 | F155: positive | G155: 0 | H155: NA | I155: 0 | J155: NA | K155: 0 | L155: NA | M155: 0 | N155: NA | O155: 0 | P155: NA | Q155: 1 | R155: positive | S155: 0 | T155: NA
A156: 155 | B156: kz | C156: NA | D156: Тауық еті қаттылау болып шықты, ал гарнирі мүлде суып қалған. Тапсырысты тез әкелгенімен, тағам сапасы ұнамады. | E156: 1 | F156: negative | G156: 0 | H156: NA | I156: 0 | J156: NA | K156: 0 | L156: NA | M156: 0 | N156: NA | O156: 1 | P156: positive | Q156: 0 | R156: NA | S156: 0 | T156: NA
A157: 156 | B157: kz | C157: NA | D157: Мантысы өте дәмді, қамыры жұқа, іші шырынды екен. Порциясы да жақсы, аш келсең тоясың. | E157: 1 | F157: positive | G157: 0 | H157: NA | I157: 0 | J157: NA | K157: 0 | L157: NA | M157: 1 | N157: positive | O157: 0 | P157: NA | Q157: 0 | R157: NA | S157: 0 | T157: NA
A158: 157 | B158: kz | C158: NA | D158: Тағамның дәмі орташа ғана, тұзы сәл көптеу болды. Қызмет көрсету жаман емес, бірақ бұл жердің асханасы онша әсер етпеді. | E158: 1 | F158: negative | G158: 1 | H158: neutral | I158: 0 | J158: NA | K158: 0 | L158: NA | M158: 0 | N158: NA | O158: 0 | P158: NA | Q158: 0 | R158: NA | S158: 0 | T158: NA
A159: 158 | B159: kz | C159: NA | D159: Балық өте жақсы дайындалған, иісі де, дәмі де жаңа екенін байқатты. Тазалығы мен жалпы қызметі де көңілге қонды. | E159: 1 | F159: positive | G159: 1 | H159: positive | I159: 0 | J159: NA | K159: 1 | L159: positive | M159: 0 | N159: NA | O159: 0 | P159: NA | Q159: 0 | R159: NA | S159: 0 | T159: NA
A160: 159 | B160: kz | C160: NA | D160: Бағасына қарасаң, тағам сапасы әлдеқайда жақсы болуы керек еді. Пастасы құрғақ, соусы аз, сондықтан аса ұнамады. | E160: 1 | F160: negative | G160: 0 | H160: NA | I160: 0 | J160: NA | K160: 0 | L160: NA | M160: 1 | N160: negative | O160: 0 | P160: NA | Q160: 0 | R160: NA | S160: 0 | T160: NA
A161: 160 | B161: kz | C161: NA | D161: Өте дәмді тағам екен, әсіресе палауы ұнады, майы да, тұзы да орнымен. Орынның өзі де жайлы, достармен тыныш отырып тамақтануға болады. | E161: 1 | F161: positive | G161: 0 | H161: NA | I161: 0 | J161: NA | K161: 0 | L161: NA | M161: 0 | N161: NA | O161: 0 | P161: NA | Q161: 1 | R161: positive | S161: 0 | T161: NA
A162: 161 | B162: kz | C162: NA | D162: Іші өте таза екен, үстелдер де, еден де жинақы болды. Осындай жерге қайта келгің келеді. | E162: 0 | F162: NA | G162: 0 | H162: NA | I162: 0 | J162: NA | K162: 1 | L162: positive | M162: 0 | N162: NA | O162: 0 | P162: NA | Q162: 0 | R162: NA | S162: 0 | T162: NA
A163: 162 | B163: kz | C163: NA | D163: Жалпы орын жаман емес, бірақ үстел үсті дұрыс сүртілмеген сияқты көрінді. Тамақ дәмді болды, алайда тазалық жағы жақсырақ болса екен. | E163: 1 | F163: positive | G163: 0 | H163: NA | I163: 0 | J163: NA | K163: 1 | L163: negative | M163: 0 | N163: NA | O163: 0 | P163: NA | Q163: 0 | R163: NA | S163: 0 | T163: NA
A164: 163 | B164: kz | C164: NA | D164: Кафенің іші тап-таза, ыдыстары да жылтырап тұр. Қызмет көрсетуімен бірге осы жағы да қатты ұнады. | E164: 0 | F164: NA | G164: 1 | H164: positive | I164: 0 | J164: NA | K164: 1 | L164: positive | M164: 0 | N164: NA | O164: 0 | P164: NA | Q164: 0 | R164: NA | S164: 0 | T164: NA
A165: 164 | B165: kz | C165: NA | D165: Дәретханасы таза болмағаны көңілге тиді. Мұндай жерде тамақтың дәмі жақсы болса да, әсер төмендеп кетеді екен. | E165: 1 | F165: positive | G165: 0 | H165: NA | I165: 0 | J165: NA | K165: 1 | L165: negative | M165: 0 | N165: NA | O165: 0 | P165: NA | Q165: 0 | R165: NA | S165: 0 | T165: NA
... A185: 184 | B185: mixed | C185: NA | D185: Кассир алып тастандаршы жумыстан менсенби турама адамды калай калай ози хиджаб киген кыз | E185: 0 | F185: NA | G185: 1 | H185: negative | I185: 0 | J185: NA | K185: 0 | L185: NA | M185: 0 | N185: NA | O185: 0 | P185: NA | Q185: 0 | R185: NA | S185: 0 | T185: NA
A186: 185 | B186: ru | C186: 5 | D186: В зале чисто, столы аккуратно протерты, находиться внутри приятно. Сразу видно, что за порядком здесь следят. | E186: 0 | F186: NA | G186: 0 | H186: NA | I186: 0 | J186: NA | K186: 1 | L186: positive | M186: 0 | N186: NA | O186: 0 | P186: NA | Q186: 0 | R186: NA | S186: 0 | T186: NA
A187: 186 | B187: ru | C187: 3 | D187: Еда вкусная, но чистота в зале оставила смешанные впечатления: на столе были крошки, и его долго не убирали. | E187: 1 | F187: positive | G187: 0 | H187: NA | I187: 0 | J187: NA | K187: 1 | L187: negative | M187: 0 | N187: NA | O187: 0 | P187: NA | Q187: 0 | R187: NA | S187: 0 | T187: NA
A188: 187 | B188: ru | C188: 5 | D188: Очень понравилось, что в заведении чисто и нет посторонних запахов. В такой атмосфере даже еда кажется еще приятнее. | E188: 0 | F188: NA | G188: 0 | H188: NA | I188: 0 | J188: NA | K188: 1 | L188: positive | M188: 0 | N188: NA | O188: 0 | P188: NA | Q188: 0 | R188: NA | S188: 0 | T188: NA
A189: 188 | B189: ru | C189: 2 | D189: В целом место неплохое, но пол был грязноват, особенно возле столиков. На такие вещи сразу обращаешь внимание. | E189: 0 | F189: NA | G189: 0 | H189: NA | I189: 0 | J189: NA | K189: 1 | L189: negative | M189: 0 | N189: NA | O189: 0 | P189: NA | Q189: 0 | R189: NA | S189: 0 | T189: NA
A190: 189 | B190: ru | C190: 5 | D190: Туалет был чистый, мыло и салфетки на месте, что для меня всегда важно. За это отдельный плюс заведению. | E190: 0 | F190: NA | G190: 0 | H190: NA | I190: 0 | J190: NA | K190: 1 | L190: positive | M190: 0 | N190: NA | O190: 0 | P190: NA | Q190: 0 | R190: NA | S190: 0 | T190: NA
A191: 190 | B191: ru | C191: 4 | D191: Персонал вежливый, заказ принесли быстро, но на подносе остались какие-то пятна. В плане гигиены хотелось бы аккуратнее. | E191: 0 | F191: NA | G191: 1 | H191: positive | I191: 0 | J191: NA | K191: 1 | L191: negative | M191: 0 | N191: NA | O191: 1 | P191: positive | Q191: 0 | R191: NA | S191: 0 | T191: NA
A192: 191 | B192: ru | C192: 5 | D192: Внутри уютно и чисто, посуда без разводов, приборы тоже аккуратные. Оставило хорошее впечатление. | E192: 0 | F192: NA | G192: 0 | H192: NA | I192: 0 | J192: NA | K192: 1 | L192: positive | M192: 0 | N192: NA | O192: 0 | P192: NA | Q192: 0 | R192: NA | S192: 0 | T192: NA
A193: 192 | B193: ru | C193: 4 | D193: Заказ понравился, но стол, за который сели, был плохо протерт. Пришлось просить, чтобы его убрали. | E193: 1 | F193: positive | G193: 0 | H193: NA | I193: 0 | J193: NA | K193: 1 | L193: negative | M193: 0 | N193: NA | O193: 0 | P193: NA | Q193: 0 | R193: NA | S193: 0 | T193: NA
A194: 193 | B194: ru | C194: 5 | D194: В заведении чисто, светло и приятно находиться. Особенно понравилось, что даже в час пик все выглядело опрятно. | E194: 0 | F194: NA | G194: 0 | H194: NA | I194: 0 | J194: NA | K194: 1 | L194: positive | M194: 0 | N194: NA | O194: 0 | P194: NA | Q194: 0 | R194: NA | S194: 0 | T194: NA
...

Sheet Aspect by Language
A1: x`
A3: Как читать: число = сколько отзывов этого языка затрагивают аспект (где аспект = 1).
A5: Aspect by language
A6: Aspect | B6: ru | C6: kz | D6: mixed | E6: Mentioned
A7: FQ | B7: =COUNTIFS(Data!$E:$E,1,Data!$B:$B,B$6) -> 561 | C7: =COUNTIFS(Data!$E:$E,1,Data!$B:$B,C$6) -> 409 | D7: =COUNTIFS(Data!$E:$E,1,Data!$B:$B,D$6) -> 159 | E7: =SUM(B7:D7) -> 1129
A8: SS | B8: =COUNTIFS(Data!$G:$G,1,Data!$B:$B,B$6) -> 458 | C8: =COUNTIFS(Data!$G:$G,1,Data!$B:$B,C$6) -> 426 | D8: =COUNTIFS(Data!$G:$G,1,Data!$B:$B,D$6) -> 212 | E8: =SUM(B8:D8) -> 1096
A9: OA | B9: =COUNTIFS(Data!$I:$I,1,Data!$B:$B,B$6) -> 224 | C9: =COUNTIFS(Data!$I:$I,1,Data!$B:$B,C$6) -> 113 | D9: =COUNTIFS(Data!$I:$I,1,Data!$B:$B,D$6) -> 17 | E9: =SUM(B9:D9) -> 354
A10: CL | B10: =COUNTIFS(Data!$K:$K,1,Data!$B:$B,B$6) -> 212 | C10: =COUNTIFS(Data!$K:$K,1,Data!$B:$B,C$6) -> 160 | D10: =COUNTIFS(Data!$K:$K,1,Data!$B:$B,D$6) -> 26 | E10: =SUM(B10:D10) -> 398
A11: PV | B11: =COUNTIFS(Data!$M:$M,1,Data!$B:$B,B$6) -> 217 | C11: =COUNTIFS(Data!$M:$M,1,Data!$B:$B,C$6) -> 59 | D11: =COUNTIFS(Data!$M:$M,1,Data!$B:$B,D$6) -> 23 | E11: =SUM(B11:D11) -> 299
A12: WS | B12: =COUNTIFS(Data!$O:$O,1,Data!$B:$B,B$6) -> 223 | C12: =COUNTIFS(Data!$O:$O,1,Data!$B:$B,C$6) -> 88 | D12: =COUNTIFS(Data!$O:$O,1,Data!$B:$B,D$6) -> 46 | E12: =SUM(B12:D12) -> 357
A13: AM | B13: =COUNTIFS(Data!$Q:$Q,1,Data!$B:$B,B$6) -> 315 | C13: =COUNTIFS(Data!$Q:$Q,1,Data!$B:$B,C$6) -> 191 | D13: =COUNTIFS(Data!$Q:$Q,1,Data!$B:$B,D$6) -> 76 | E13: =SUM(B13:D13) -> 582
A14: LO | B14: =COUNTIFS(Data!$S:$S,1,Data!$B:$B,B$6) -> 171 | C14: =COUNTIFS(Data!$S:$S,1,Data!$B:$B,C$6) -> 97 | D14: =COUNTIFS(Data!$S:$S,1,Data!$B:$B,D$6) -> 6 | E14: =SUM(B14:D14) -> 274
A15: Total mentions | B15: =SUM(B7:B14) -> 2381 | C15: =SUM(C7:C14) -> 1543 | D15: =SUM(D7:D14) -> 565 | E15: =SUM(E7:E14) -> 4489
A17: Примечание: один отзыв может попадать сразу в несколько аспектов, поэтому "Total mentions" — это сумма упоминаний аспектов, а не уникальных отзывов.
